<?xml version="1.0"?>
<robot name="minimal_spacing_gripper">

  <!-- gripper base -->
  <link name="gripper_base">
    <inertial>
      <origin xyz="0 0 0" rpy="0 0 0"/>
      <mass value="0.05"/>
      <inertia ixx="0.0005" ixy="0" ixz="0" iyy="0.0005" iyz="0" izz="0.0005"/>
    </inertial>
    <visual>
      <origin xyz="0 0 0" rpy="0 0 0"/>
      <geometry>
        <box size="0.02 0.02 0.02"/>
      </geometry>
      <material name="gray">
        <color rgba="0.5 0.5 0.5 1"/>
      </material>
    </visual>
    <collision>
      <origin xyz="0 0 0" rpy="0 0 0"/>
      <geometry>
        <box size="0.02 0.02 0.02"/>
      </geometry>
    </collision>
  </link>

  <!-- left finger -->
  <link name="left_finger">
    <inertial>
      <origin xyz="0 0 0" rpy="0 0 0"/>
      <mass value="0.01"/>
      <inertia ixx="0.00005" ixy="0" ixz="0" iyy="0.00005" iyz="0" izz="0.00005"/>
    </inertial>
    <visual>
      <origin xyz="0 0 0.03" rpy="0 0 0"/>
      <geometry>
        <box size="0.008 0.002 0.06"/>
      </geometry>
      <material name="dark_gray">
        <color rgba="0.3 0.3 0.3 1"/>
      </material>
    </visual>
    <collision>
      <origin xyz="0 0 0.03" rpy="0 0 0"/>
      <geometry>
        <box size="0.008 0.002 0.06"/>
      </geometry>
    </collision>
  </link>

  <!-- right finger -->
  <link name="right_finger">
    <inertial>
      <origin xyz="0 0 0" rpy="0 0 0"/>
      <mass value="0.01"/>
      <inertia ixx="0.00005" ixy="0" ixz="0" iyy="0.00005" iyz="0" izz="0.00005"/>
    </inertial>
    <visual>
      <origin xyz="0 0 0.03" rpy="0 0 0"/>
      <geometry>
        <box size="0.008 0.002 0.06"/>
      </geometry>
      <material name="dark_gray">
        <color rgba="0.3 0.3 0.3 1"/>
      </material>
    </visual>
    <collision>
      <origin xyz="0 0 0.03" rpy="0 0 0"/>
      <geometry>
        <box size="0.008 0.002 0.06"/>
      </geometry>
    </collision>
  </link>

  <!-- left finger joint - MINIMAL SPACING -->
  <joint name="left_finger_joint" type="prismatic">
    <parent link="gripper_base"/>
    <child link="left_finger"/>
    <origin xyz="0 0.0005 0.03"/>
    <axis xyz="0 1 0"/>
    <limit lower="0.0" upper="0.003" effort="10" velocity="0.1"/>
  </joint>

  <!-- right finger joint - MINIMAL SPACING -->
  <joint name="right_finger_joint" type="prismatic">
    <parent link="gripper_base"/>
    <child link="right_finger"/>
    <origin xyz="0 -0.0005 0.03"/>
    <axis xyz="0 -1 0"/>
    <limit lower="0.0" upper="0.003" effort="10" velocity="0.1"/>
  </joint>

</robot>
